1111_training.out

Traceback (most recent call last):
  File "C:\Users\BI_SEON\Anaconda3\envs\dl\lib\site-packages\tensorflow\python\framework\common_shapes.py", line 686, in _call_cpp_shape_fn_impl
    input_tensors_as_shapes, status)
  File "C:\Users\BI_SEON\Anaconda3\envs\dl\lib\site-packages\tensorflow\python\framework\errors_impl.py", line 473, in __exit__
    c_api.TF_GetCode(self.status.status))
tensorflow.python.framework.errors_impl.InvalidArgumentError: Dimension 1 in both shapes must be equal, but are 8 and 4 for 'generator/concat' (op: 'ConcatV2') with input shapes: [1,8,8,512], [1,4,4,512], [] and with computed input tensors: input[2] = <3>.

During handling of the above exception, another exception occurred:

Traceback (most recent call last):
  File ".\main.py", line 83, in <module>
    tf.app.run()
  File "C:\Users\BI_SEON\Anaconda3\envs\dl\lib\site-packages\tensorflow\python\platform\app.py", line 48, in run
    _sys.exit(main(_sys.argv[:1] + flags_passthrough))
  File ".\main.py", line 73, in main
    checkpoint_dir=args.checkpoint_dir, sample_dir=args.sample_dir, test_dir=args.test_dir)
  File "C:\Users\BI_SEON\Documents\muhan_records\model_code\fin_model.py", line 73, in __init__
    self.build_model()
  File "C:\Users\BI_SEON\Documents\muhan_records\model_code\fin_model.py", line 84, in build_model
    self.fake_B = self.generator(self.real_A)
  File "C:\Users\BI_SEON\Documents\muhan_records\model_code\fin_model.py", line 299, in generator
    d0 = tf.concat([d0, e8], 3)
  File "C:\Users\BI_SEON\Anaconda3\envs\dl\lib\site-packages\tensorflow\python\ops\array_ops.py", line 1099, in concat
    return gen_array_ops._concat_v2(values=values, axis=axis, name=name)
  File "C:\Users\BI_SEON\Anaconda3\envs\dl\lib\site-packages\tensorflow\python\ops\gen_array_ops.py", line 705, in _concat_v2
    "ConcatV2", values=values, axis=axis, name=name)
  File "C:\Users\BI_SEON\Anaconda3\envs\dl\lib\site-packages\tensorflow\python\framework\op_def_library.py", line 787, in _apply_op_helper
    op_def=op_def)
  File "C:\Users\BI_SEON\Anaconda3\envs\dl\lib\site-packages\tensorflow\python\framework\ops.py", line 2958, in create_op
    set_shapes_for_outputs(ret)
  File "C:\Users\BI_SEON\Anaconda3\envs\dl\lib\site-packages\tensorflow\python\framework\ops.py", line 2209, in set_shapes_for_outputs
    shapes = shape_func(op)
  File "C:\Users\BI_SEON\Anaconda3\envs\dl\lib\site-packages\tensorflow\python\framework\ops.py", line 2159, in call_with_requiring
    return call_cpp_shape_fn(op, require_shape_fn=True)
  File "C:\Users\BI_SEON\Anaconda3\envs\dl\lib\site-packages\tensorflow\python\framework\common_shapes.py", line 627, in call_cpp_shape_fn
    require_shape_fn)
  File "C:\Users\BI_SEON\Anaconda3\envs\dl\lib\site-packages\tensorflow\python\framework\common_shapes.py", line 691, in _call_cpp_shape_fn_impl
    raise ValueError(err.message)
ValueError: Dimension 1 in both shapes must be equal, but are 8 and 4 for 'generator/concat' (op: 'ConcatV2') with input shapes: [1,8,8,512], [1,4,4,512], [] and with computed input tensors: input[2] = <3>.


d0 = [1,8,8,512]
e8 = [1,4,4,512]